<mujoco model="ant">
  <compiler angle="degree" coordinate="local" inertiafromgeom="true"/>
  <option integrator="RK4" timestep="0.01" gravity="0 0 -9.81" />
  <custom>
    <numeric data="0.0 0.0 0.55 1.0 0.0 0.0 0.0 0.0 1.0 0.0 -1.0 0.0 -1.0 0.0 1.0" name="init_qpos"/>
  </custom>
  <default>
    <joint armature="1" damping="1" limited="true"/>
    <geom conaffinity="0" condim="3" density="5.0" friction="1 0.5 0.5" margin="0.01" rgba="0.8 0.6 0.4 1"/>
  </default>
  <asset>
    <texture builtin="gradient" height="100" rgb1="1 1 1" rgb2="0 0 0" type="skybox" width="100"/>
    <texture builtin="flat" height="1278" mark="cross" markrgb="1 1 1" name="texgeom" random="0.01" rgb1="0.8 0.6 0.4" rgb2="0.8 0.6 0.4" type="cube" width="127"/>
    <texture builtin="checker" height="100" name="texplane" rgb1="0 0 0" rgb2="0.8 0.8 0.8" type="2d" width="100"/>
    <material name="MatPlane" reflectance="0.5" shininess="1" specular="1" texrepeat="60 60" texture="texplane"/>
    <material name="geom" texture="texgeom" texuniform="true"/>
  </asset>
  <worldbody>
    <light cutoff="100" diffuse="1 1 1" dir="-0 0 -1.3" directional="true" exponent="1" pos="0 0 1.3" specular=".1 .1 .1"/>
    <geom conaffinity="1" condim="3" material="MatPlane" name="floor" pos="0 0 0" rgba="0.8 0.9 0.8 1" size="40 40 40" type="plane"/>
      <!-- spider body -->
    <body name="spider" pos="0 0 1">
        <site name="spider_site" pos="0 0 0" size="0.01" />
        <geom name="spider_geom" type="box" size="0.80 0.50 0.05"/>
        <joint type="free"/>
        <!-- Spider leg: front right corner -->
        <body name="front_right_leg" pos="0.7 0.5 0" euler="0 90 0">
            <joint name="hip_front_right" type="hinge" axis="0 1 0" pos="0 0 0"  range="-90 90"/>
            <geom name="front_right_leg_geom" type="capsule" fromto="0 0 0 0.6 0 0"  size="0.05"/>
        </body>
        <!-- Spider leg: back left corner -->
        <body name="back_right_leg" pos="-0.7 0.5 0" euler="0 90 0">
            <joint name="hip_back_right" type="hinge" axis="0 1 0" pos="0 0 0"  range="-90 90"/>
            <geom name="back_right_leg_geom" type="capsule" fromto="0 0 0 0.6 0 0"  size="0.05"/>
        </body>
                <!-- Spider leg: front right corner -->
        <body name="front_left_leg" pos="0.7 -0.5 0" euler="0 90 0">
            <joint name="hip_front_left" type="hinge" axis="0 1 0" pos="0 0 0"  range="-90 90"/>
            <geom name="front_left_leg_geom" type="capsule" fromto="0 0 0 0.6 0 0"  size="0.05"/>
        </body>
        <!-- Spider leg: back left corner -->
        <body name="back_left_leg" pos="-0.7 -0.5 0" euler="0 90 0">
            <joint name="hip_back_left" type="hinge" axis="0 1 0" pos="0 0 0"  range="-90 90"/>
            <geom name="back_left_leg_geom" type="capsule" fromto="0 0 0 0.6 0 0"  size="0.05"/>
        </body>
        
    </body>
   </worldbody>
  <actuator>
    <position joint="hip_front_right" kp="10"/>
    <position joint="hip_back_right" kp="10"/>
    <position joint="hip_front_left" kp="10"/>
    <position joint="hip_back_left" kp="10"/>
  </actuator>
  <sensor>
    <framepos objtype="body" objname="spider"/>
   <velocimeter site="spider_site"/>
  </sensor>

</mujoco>